const x = 5;
try {
  x = 2;
} catch (err) {
  console.log(`erro ${err}`);
}
